Workbook
Name Slicer_Month: #N/A
Name Slicer_Product_Category: #N/A
Name Slicer_Quarter: #N/A
Name Slicer_Region: #N/A
Name Slicer_Sales_Method: #N/A

Sheet Pivot Tables
A2: Product | H2: Month
A3: Row Labels | B3: Sum of Total Sales | C3: Sum of Operating Profit | H3: Row Labels | I3: Sum of Total Sales
A4: Men's Apparel | B4: 16520632 | C4: 6381405.3 | H4: Jan | I4: 9744767
A5: Men's Athletic Footwear | B5: 20577180 | C5: 7437456.9 | H5: Feb | I5: 8263853
A6: Men's Street Footwear | B6: 27680769 | C6: 11629046 | H6: Mar | I6: 7694984
A7: Women's Apparel | B7: 23870985 | C7: 9685220.6 | H7: Apr | I7: 9691420
A8: Women's Athletic Footwear | B8: 14315521 | C8: 5597822.4 | H8: May | I8: 10741720
A9: Women's Street Footwear | B9: 17201563 | C9: 6494016.8 | H9: Jun | I9: 9803147
A10: Grand Total | B10: 120166650 | C10: 47224968 | H10: Jul | I10: 12550419
H11: Aug | I11: 12293226
H12: Sep | I12: 10405584
H13: Oct | I13: 8538758
H14: Nov | I14: 9023440
A15: Retailer | H15: Dec | I15: 11415332
A16: Row Labels | B16: Sum of Total Sales | H16: Grand Total | I16: 120166650
A17: Amazon | B17: 10096987
A18: Walmart | B18: 10506085
A19: Kohl's | B19: 13512453
A20: Sports Direct | B20: 24616622 | H20: Sales category by region
A21: Foot Locker | B21: 29024945 | H21: Row Labels | I21: Sum of Total Sales
A22: West Gear | B22: 32409558 | H22: Apparel | I22: 0.33613001
A23: Grand Total | B23: 120166650 | H23: Footwear | I23: 0.66386999
H24: Grand Total | I24: 1
A28: Sales Method
A29: Row Labels | B29: Sum of Total Sales | D29: //Show val as %grand total
A30: In-store | B30: 35664375 | H30: KPIs
A31: Outlet | B31: 39536618 | H31: Sum of Total Sales | I31: Sum of Operating Profit | J31: Average of Operating Margin | K31: Average of Units Sold
A32: Online | B32: 44965657 | H32: 120166650 | I32: 47224968 | J32: 0.42299129 | K32: 256.93004
A33: Grand Total | B33: 120166650
H36: Region
H37: Sum of Total Sales | I37: Column Labels
A38: Region | H38: Row Labels | I38: Midwest | J38: Northeast | K38: South | L38: Southeast | M38: West | N38: Grand Total
A39: Row Labels | B39: Sum of Operating Profit | H39: Men's Street Footwear | I39: 4707360 | J39: 6841324 | K39: 4048261 | L39: 4693836 | M39: 7389988 | N39: 27680769
A40: West | B40: 13017584 | H40: Women's Apparel | I40: 3453008 | J40: 5045208 | K40: 4224937 | L40: 4109786 | M40: 7038046 | N40: 23870985
A41: Northeast | B41: 9732773.9 | H41: Men's Athletic Footwear | I41: 2619289 | J41: 3895862 | K41: 3647045 | L41: 3653645 | M41: 6761339 | N41: 20577180
A42: South | B42: 9221605.3 | H42: Women's Street Footwear | I42: 1997448 | J42: 3152823 | K42: 3242822 | L42: 3059884 | M42: 5748586 | N42: 17201563
A43: Southeast | B43: 8393059.2 | H43: Men's Apparel | I43: 2223786 | J43: 3475037 | K43: 2811194 | L43: 3183237 | M43: 4827378 | N43: 16520632
A44: Midwest | B44: 6859945.2 | H44: Women's Athletic Footwear | I44: 1673543 | J44: 2668013 | K44: 2629097 | L44: 2674048 | M44: 4670820 | N44: 14315521
A45: Grand Total | B45: 47224968 | H45: Grand Total | I45: 16674434 | J45: 25078267 | K45: 20603356 | L45: 21374436 | M45: 36436157 | N45: 120166650
A49: State
...

Sheet Analysis
K2: Heat Map
A3: MAP | K3: Product | L3: Midwest | M3: Northeast | N3: South | O3: Southeast | P3: West
A4: Top | K4: ='Pivot Tables'!H39 -> Men's Street Footwear | L4: ='Pivot Tables'!I39 -> 4707360 | M4: ='Pivot Tables'!J39 -> 6841324 | N4: ='Pivot Tables'!K39 -> 4048261 | O4: ='Pivot Tables'!L39 -> 4693836 | P4: ='Pivot Tables'!M39 -> 7389988
A5: State | B5: Total Sales | K5: ='Pivot Tables'!H40 -> Women's Apparel | L5: ='Pivot Tables'!I40 -> 3453008 | M5: ='Pivot Tables'!J40 -> 5045208 | N5: ='Pivot Tables'!K40 -> 4224937 | O5: ='Pivot Tables'!L40 -> 4109786 | P5: ='Pivot Tables'!M40 -> 7038046
A6: ='Pivot Tables'!A51 -> Alabama | B6: ='Pivot Tables'!B51 -> 2513424 | K6: ='Pivot Tables'!H41 -> Men's Athletic Footwear | L6: ='Pivot Tables'!I41 -> 2619289 | M6: ='Pivot Tables'!J41 -> 3895862 | N6: ='Pivot Tables'!K41 -> 3647045 | O6: ='Pivot Tables'!L41 -> 3653645 | P6: ='Pivot Tables'!M41 -> 6761339
A7: ='Pivot Tables'!A52 -> California | B7: ='Pivot Tables'!B52 -> 8580508 | K7: ='Pivot Tables'!H42 -> Women's Street Footwear | L7: ='Pivot Tables'!I42 -> 1997448 | M7: ='Pivot Tables'!J42 -> 3152823 | N7: ='Pivot Tables'!K42 -> 3242822 | O7: ='Pivot Tables'!L42 -> 3059884 | P7: ='Pivot Tables'!M42 -> 5748586
A8: ='Pivot Tables'!A53 -> Colorado | B8: ='Pivot Tables'!B53 -> 2569036 | K8: ='Pivot Tables'!H43 -> Men's Apparel | L8: ='Pivot Tables'!I43 -> 2223786 | M8: ='Pivot Tables'!J43 -> 3475037 | N8: ='Pivot Tables'!K43 -> 2811194 | O8: ='Pivot Tables'!L43 -> 3183237 | P8: ='Pivot Tables'!M43 -> 4827378
A9: ='Pivot Tables'!A54 -> Florida | B9: ='Pivot Tables'!B54 -> 7820589 | K9: ='Pivot Tables'!H44 -> Women's Athletic Footwear | L9: ='Pivot Tables'!I44 -> 1673543 | M9: ='Pivot Tables'!J44 -> 2668013 | N9: ='Pivot Tables'!K44 -> 2629097 | O9: ='Pivot Tables'!L44 -> 2674048 | P9: ='Pivot Tables'!M44 -> 4670820
A10: ='Pivot Tables'!A55 -> Georgia | B10: ='Pivot Tables'!B55 -> 2708591
A11: ='Pivot Tables'!A56 -> Hawaii | B11: ='Pivot Tables'!B56 -> 2734457
A12: ='Pivot Tables'!A57 -> Idaho | B12: ='Pivot Tables'!B57 -> 2742753
A13: ='Pivot Tables'!A58 -> Louisiana | B13: ='Pivot Tables'!B58 -> 3377031
A14: ='Pivot Tables'!A59 -> Michigan | B14: ='Pivot Tables'!B59 -> 2287283
A15: ='Pivot Tables'!A60 -> Nevada | B15: ='Pivot Tables'!B60 -> 2981134
A16: ='Pivot Tables'!A61 -> New Hampshire | B16: ='Pivot Tables'!B61 -> 2339267
A17: ='Pivot Tables'!A62 -> New Mexico | B17: ='Pivot Tables'!B62 -> 2824641
A18: ='Pivot Tables'!A63 -> New York | B18: ='Pivot Tables'!B63 -> 8670464
A19: ='Pivot Tables'!A64 -> North Carolina | B19: ='Pivot Tables'!B64 -> 2936581
A20: ='Pivot Tables'!A65 -> Oregon | B20: ='Pivot Tables'!B65 -> 3047049
A21: ='Pivot Tables'!A66 -> South Carolina | B21: ='Pivot Tables'!B66 -> 3593112
... A25: ='Pivot Tables'!A70 -> Washington | B25: ='Pivot Tables'!B70 -> 3222093

Sheet Data Sales Adidas
C2: Adidas Sales Database
B5: Retailer | C5: Retailer ID | D5: Invoice Date | E5: Region | F5: State | G5: City | H5: Product | I5: Price per Unit | J5: Units Sold | K5: Total Sales | L5: Operating Profit | M5: Operating Margin | N5: Sales Method | O5: Year | P5: Month | Q5: Quarter | R5: Product Category | S5: Profir Per Unit
B6: Foot Locker | C6: 1185732 | D6: 43831 | E6: Northeast | F6: New York | G6: New York | H6: Men's Street Footwear | I6: 50 | J6: 1200 | K6: 60000 | L6: 30000 | M6: 0.5 | N6: In-store | O6: =YEAR(D6) -> 2020 | P6: =TEXT(D6,"MMM") -> Jan | Q6: ="Q"&ROUNDUP(MONTH(D6)/3,0) -> Q1 | R6: =IF(ISNUMBER(SEARCH("Footwear",H6)),"Footwear",IF(ISNUMBER(SEARCH("Apparel",H6)),"Apparel","Accessories")) -> Footwear | S6: =L6/J6 -> 25 | U6: Formulas used
B7: Foot Locker | C7: 1185732 | D7: 43832 | E7: Northeast | F7: New York | G7: New York | H7: Men's Athletic Footwear | I7: 50 | J7: 1000 | K7: 50000 | L7: 15000 | M7: 0.3 | N7: In-store | O7: =YEAR(D7) -> 2020 | P7: =TEXT(D7,"MMM") -> Jan | Q7: ="Q"&ROUNDUP(MONTH(D7)/3,0) -> Q1 | R7: =IF(ISNUMBER(SEARCH("Footwear",H7)),"Footwear",IF(ISNUMBER(SEARCH("Apparel",H7)),"Apparel","Accessories")) -> Footwear | S7: =L7/J7 -> 15 | U7: Year
B8: Foot Locker | C8: 1185732 | D8: 43833 | E8: Northeast | F8: New York | G8: New York | H8: Women's Street Footwear | I8: 40 | J8: 1000 | K8: 40000 | L8: 14000 | M8: 0.35 | N8: In-store | O8: =YEAR(D8) -> 2020 | P8: =TEXT(D8,"MMM") -> Jan | Q8: ="Q"&ROUNDUP(MONTH(D8)/3,0) -> Q1 | R8: =IF(ISNUMBER(SEARCH("Footwear",H8)),"Footwear",IF(ISNUMBER(SEARCH("Apparel",H8)),"Apparel","Accessories")) -> Footwear | S8: =L8/J8 -> 14 | U8: Month/Text(..,"MMMM")
B9: Foot Locker | C9: 1185732 | D9: 43834 | E9: Northeast | F9: New York | G9: New York | H9: Women's Athletic Footwear | I9: 45 | J9: 850 | K9: 38250 | L9: 13387.5 | M9: 0.35 | N9: In-store | O9: =YEAR(D9) -> 2020 | P9: =TEXT(D9,"MMM") -> Jan | Q9: ="Q"&ROUNDUP(MONTH(D9)/3,0) -> Q1 | R9: =IF(ISNUMBER(SEARCH("Footwear",H9)),"Footwear",IF(ISNUMBER(SEARCH("Apparel",H9)),"Apparel","Accessories")) -> Footwear | S9: =L9/J9 -> 15.75 | U9: "Q"&ROUNDUP(MONTH(D6)/3,0)
B10: Foot Locker | C10: 1185732 | D10: 43835 | E10: Northeast | F10: New York | G10: New York | H10: Men's Apparel | I10: 60 | J10: 900 | K10: 54000 | L10: 16200 | M10: 0.3 | N10: In-store | O10: =YEAR(D10) -> 2020 | P10: =TEXT(D10,"MMM") -> Jan | Q10: ="Q"&ROUNDUP(MONTH(D10)/3,0) -> Q1 | R10: =IF(ISNUMBER(SEARCH("Footwear",H10)),"Footwear",IF(ISNUMBER(SEARCH("Apparel",H10)),"Apparel","Accessories")) -> Apparel | S10: =L10/J10 -> 18 | U10: IF(ISNUMBER(SEARCH("Footwear",H6)),"Footwear",IF(ISNUMBER(SEARCH("Apparel",H6)),"Apparel","Accessories"))
B11: Foot Locker | C11: 1185732 | D11: 43836 | E11: Northeast | F11: New York | G11: New York | H11: Women's Apparel | I11: 50 | J11: 1000 | K11: 50000 | L11: 12500 | M11: 0.25 | N11: In-store | O11: =YEAR(D11) -> 2020 | P11: =TEXT(D11,"MMM") -> Jan | Q11: ="Q"&ROUNDUP(MONTH(D11)/3,0) -> Q1 | R11: =IF(ISNUMBER(SEARCH("Footwear",H11)),"Footwear",IF(ISNUMBER(SEARCH("Apparel",H11)),"Apparel","Accessories")) -> Apparel | S11: =L11/J11 -> 12.5
B12: Foot Locker | C12: 1185732 | D12: 43837 | E12: Northeast | F12: New York | G12: New York | H12: Men's Street Footwear | I12: 50 | J12: 1250 | K12: 62500 | L12: 31250 | M12: 0.5 | N12: In-store | O12: =YEAR(D12) -> 2020 | P12: =TEXT(D12,"MMM") -> Jan | Q12: ="Q"&ROUNDUP(MONTH(D12)/3,0) -> Q1 | R12: =IF(ISNUMBER(SEARCH("Footwear",H12)),"Footwear",IF(ISNUMBER(SEARCH("Apparel",H12)),"Apparel","Accessories")) -> Footwear | S12: =L12/J12 -> 25
B13: Foot Locker | C13: 1185732 | D13: 43838 | E13: Northeast | F13: New York | G13: New York | H13: Men's Athletic Footwear | I13: 50 | J13: 900 | K13: 45000 | L13: 13500 | M13: 0.3 | N13: Outlet | O13: =YEAR(D13) -> 2020 | P13: =TEXT(D13,"MMM") -> Jan | Q13: ="Q"&ROUNDUP(MONTH(D13)/3,0) -> Q1 | R13: =IF(ISNUMBER(SEARCH("Footwear",H13)),"Footwear",IF(ISNUMBER(SEARCH("Apparel",H13)),"Apparel","Accessories")) -> Footwear | S13: =L13/J13 -> 15 | U13: Error
B14: Foot Locker | C14: 1185732 | D14: 43851 | E14: Northeast | F14: New York | G14: New York | H14: Women's Street Footwear | I14: 40 | J14: 950 | K14: 38000 | L14: 13300 | M14: 0.35 | N14: Outlet | O14: =YEAR(D14) -> 2020 | P14: =TEXT(D14,"MMM") -> Jan | Q14: ="Q"&ROUNDUP(MONTH(D14)/3,0) -> Q1 | R14: =IF(ISNUMBER(SEARCH("Footwear",H14)),"Footwear",IF(ISNUMBER(SEARCH("Apparel",H14)),"Apparel","Accessories")) -> Footwear | S14: =L14/J14 -> 14 | U14: Sales* Unit
B15: Foot Locker | C15: 1185732 | D15: 43852 | E15: Northeast | F15: New York | G15: New York | H15: Women's Athletic Footwear | I15: 45 | J15: 825 | K15: 37125 | L15: 12993.75 | M15: 0.35 | N15: Outlet | O15: =YEAR(D15) -> 2020 | P15: =TEXT(D15,"MMM") -> Jan | Q15: ="Q"&ROUNDUP(MONTH(D15)/3,0) -> Q1 | R15: =IF(ISNUMBER(SEARCH("Footwear",H15)),"Footwear",IF(ISNUMBER(SEARCH("Apparel",H15)),"Apparel","Accessories")) -> Footwear | S15: =L15/J15 -> 15.75 | U15: Marging *Sales
B16: Foot Locker | C16: 1185732 | D16: 43853 | E16: Northeast | F16: New York | G16: New York | H16: Men's Apparel | I16: 60 | J16: 900 | K16: 54000 | L16: 16200 | M16: 0.3 | N16: Outlet | O16: =YEAR(D16) -> 2020 | P16: =TEXT(D16,"MMM") -> Jan | Q16: ="Q"&ROUNDUP(MONTH(D16)/3,0) -> Q1 | R16: =IF(ISNUMBER(SEARCH("Footwear",H16)),"Footwear",IF(ISNUMBER(SEARCH("Apparel",H16)),"Apparel","Accessories")) -> Apparel | S16: =L16/J16 -> 18
B17: Foot Locker | C17: 1185732 | D17: 43854 | E17: Northeast | F17: New York | G17: New York | H17: Women's Apparel | I17: 50 | J17: 1000 | K17: 50000 | L17: 12500 | M17: 0.25 | N17: Outlet | O17: =YEAR(D17) -> 2020 | P17: =TEXT(D17,"MMM") -> Jan | Q17: ="Q"&ROUNDUP(MONTH(D17)/3,0) -> Q1 | R17: =IF(ISNUMBER(SEARCH("Footwear",H17)),"Footwear",IF(ISNUMBER(SEARCH("Apparel",H17)),"Apparel","Accessories")) -> Apparel | S17: =L17/J17 -> 12.5
B18: Foot Locker | C18: 1185732 | D18: 43855 | E18: Northeast | F18: New York | G18: New York | H18: Men's Street Footwear | I18: 50 | J18: 1220 | K18: 61000 | L18: 30500 | M18: 0.5 | N18: Outlet | O18: =YEAR(D18) -> 2020 | P18: =TEXT(D18,"MMM") -> Jan | Q18: ="Q"&ROUNDUP(MONTH(D18)/3,0) -> Q1 | R18: =IF(ISNUMBER(SEARCH("Footwear",H18)),"Footwear",IF(ISNUMBER(SEARCH("Apparel",H18)),"Apparel","Accessories")) -> Footwear | S18: =L18/J18 -> 25
B19: Foot Locker | C19: 1185732 | D19: 43856 | E19: Northeast | F19: New York | G19: New York | H19: Men's Athletic Footwear | I19: 50 | J19: 925 | K19: 46250 | L19: 13875 | M19: 0.3 | N19: Outlet | O19: =YEAR(D19) -> 2020 | P19: =TEXT(D19,"MMM") -> Jan | Q19: ="Q"&ROUNDUP(MONTH(D19)/3,0) -> Q1 | R19: =IF(ISNUMBER(SEARCH("Footwear",H19)),"Footwear",IF(ISNUMBER(SEARCH("Apparel",H19)),"Apparel","Accessories")) -> Footwear | S19: =L19/J19 -> 15
B20: Foot Locker | C20: 1185732 | D20: 43857 | E20: Northeast | F20: New York | G20: New York | H20: Women's Street Footwear | I20: 40 | J20: 950 | K20: 38000 | L20: 13300 | M20: 0.35 | N20: Outlet | O20: =YEAR(D20) -> 2020 | P20: =TEXT(D20,"MMM") -> Jan | Q20: ="Q"&ROUNDUP(MONTH(D20)/3,0) -> Q1 | R20: =IF(ISNUMBER(SEARCH("Footwear",H20)),"Footwear",IF(ISNUMBER(SEARCH("Apparel",H20)),"Apparel","Accessories")) -> Footwear | S20: =L20/J20 -> 14
B21: Foot Locker | C21: 1185732 | D21: 43858 | E21: Northeast | F21: New York | G21: New York | H21: Women's Athletic Footwear | I21: 45 | J21: 800 | K21: 36000 | L21: 12600 | M21: 0.35 | N21: Outlet | O21: =YEAR(D21) -> 2020 | P21: =TEXT(D21,"MMM") -> Jan | Q21: ="Q"&ROUNDUP(MONTH(D21)/3,0) -> Q1 | R21: =IF(ISNUMBER(SEARCH("Footwear",H21)),"Footwear",IF(ISNUMBER(SEARCH("Apparel",H21)),"Apparel","Accessories")) -> Footwear | S21: =L21/J21 -> 15.75
B22: Foot Locker | C22: 1185732 | D22: 43859 | E22: Northeast | F22: New York | G22: New York | H22: Men's Apparel | I22: 60 | J22: 850 | K22: 51000 | L22: 15300 | M22: 0.3 | N22: Outlet | O22: =YEAR(D22) -> 2020 | P22: =TEXT(D22,"MMM") -> Jan | Q22: ="Q"&ROUNDUP(MONTH(D22)/3,0) -> Q1 | R22: =IF(ISNUMBER(SEARCH("Footwear",H22)),"Footwear",IF(ISNUMBER(SEARCH("Apparel",H22)),"Apparel","Accessories")) -> Apparel | S22: =L22/J22 -> 18
B23: Foot Locker | C23: 1185732 | D23: 43860 | E23: Northeast | F23: New York | G23: New York | H23: Women's Apparel | I23: 50 | J23: 950 | K23: 47500 | L23: 11875 | M23: 0.25 | N23: Outlet | O23: =YEAR(D23) -> 2020 | P23: =TEXT(D23,"MMM") -> Jan | Q23: ="Q"&ROUNDUP(MONTH(D23)/3,0) -> Q1 | R23: =IF(ISNUMBER(SEARCH("Footwear",H23)),"Footwear",IF(ISNUMBER(SEARCH("Apparel",H23)),"Apparel","Accessories")) -> Apparel | S23: =L23/J23 -> 12.5
B24: Foot Locker | C24: 1185732 | D24: 43861 | E24: Northeast | F24: New York | G24: New York | H24: Men's Street Footwear | I24: 50 | J24: 1200 | K24: 60000 | L24: 30000 | M24: 0.5 | N24: Outlet | O24: =YEAR(D24) -> 2020 | P24: =TEXT(D24,"MMM") -> Jan | Q24: ="Q"&ROUNDUP(MONTH(D24)/3,0) -> Q1 | R24: =IF(ISNUMBER(SEARCH("Footwear",H24)),"Footwear",IF(ISNUMBER(SEARCH("Apparel",H24)),"Apparel","Accessories")) -> Footwear | S24: =L24/J24 -> 25
B25: Foot Locker | C25: 1185732 | D25: 43862 | E25: Northeast | F25: New York | G25: New York | H25: Men's Athletic Footwear | I25: 50 | J25: 900 | K25: 45000 | L25: 13500 | M25: 0.3 | N25: Outlet | O25: =YEAR(D25) -> 2020 | P25: =TEXT(D25,"MMM") -> Feb | Q25: ="Q"&ROUNDUP(MONTH(D25)/3,0) -> Q1 | R25: =IF(ISNUMBER(SEARCH("Footwear",H25)),"Footwear",IF(ISNUMBER(SEARCH("Apparel",H25)),"Apparel","Accessories")) -> Footwear | S25: =L25/J25 -> 15
B26: Foot Locker | C26: 1185732 | D26: 43863 | E26: Northeast | F26: New York | G26: New York | H26: Women's Street Footwear | I26: 40 | J26: 900 | K26: 36000 | L26: 12600 | M26: 0.35 | N26: Outlet | O26: =YEAR(D26) -> 2020 | P26: =TEXT(D26,"MMM") -> Feb | Q26: ="Q"&ROUNDUP(MONTH(D26)/3,0) -> Q1 | R26: =IF(ISNUMBER(SEARCH("Footwear",H26)),"Footwear",IF(ISNUMBER(SEARCH("Apparel",H26)),"Apparel","Accessories")) -> Footwear | S26: =L26/J26 -> 14
B27: Foot Locker | C27: 1185732 | D27: 43864 | E27: Northeast | F27: New York | G27: New York | H27: Women's Athletic Footwear | I27: 45 | J27: 825 | K27: 37125 | L27: 12993.75 | M27: 0.35 | N27: Outlet | O27: =YEAR(D27) -> 2020 | P27: =TEXT(D27,"MMM") -> Feb | Q27: ="Q"&ROUNDUP(MONTH(D27)/3,0) -> Q1 | R27: =IF(ISNUMBER(SEARCH("Footwear",H27)),"Footwear",IF(ISNUMBER(SEARCH("Apparel",H27)),"Apparel","Accessories")) -> Footwear | S27: =L27/J27 -> 15.75
... B9653: Foot Locker | C9653: 1185732 | D9653: 44249 | E9653: Northeast | F9653: New Hampshire | G9653: Manchester | H9653: Women's Street Footwear | I9653: 29 | J9653: 83 | K9653: 2407 | L9653: 649.89 | M9653: 0.27 | N9653: Outlet | O9653: =YEAR(D9653) -> 2021 | P9653: =TEXT(D9653,"MMM") -> Feb | Q9653: ="Q"&ROUNDUP(MONTH(D9653)/3,0) -> Q1 | R9653: =IF(ISNUMBER(SEARCH("Footwear",H9653)),"Footwear",IF(ISNUMBER(SEARCH("Apparel",H9653)),"Apparel","Accessories")) -> Footwear | S9653: =L9653/J9653 -> 7.83

Sheet Dashboard
